<?xml version="1.0" ?>
<!-- =================================================================================== -->
<!-- |    This document was autogenerated by xacro from /home/robotics/ros_ws/src/robotics/robotics_support/urdf/robots/irb6660_urdf.xacro | -->
<!-- |    EDITING THIS FILE BY HAND IS NOT RECOMMENDED                                 | -->
<!-- =================================================================================== -->
<robot name="irb6660_robot">
    <!-- ABB IRB6660 Robot -->
    <!-- Xacro Agruments and Default Values -->
    <arg default="robot" name="prefix" />
    <arg default="world" name="ref_link" />
    <arg default="0.000 0.000 0.000" name="ref_xyz" />
    <arg default="0.0 0.0 0.0" name="ref_rpy" />
    <!-- Conversion were obtained from http://www.e-paint.co.uk/Lab_values.asp
       unless otherwise stated. -->
    <!-- link list -->
    <link name="robot_base_link">
        <visual>
            <origin rpy="0 0 0" xyz="0 0 0" />
            <geometry>
                <mesh filename="package://abb_irb6660_support/meshes/irb6660/visual/base_link.stl" />
            </geometry>
            <material name="">
                <color rgba="0.7372549 0.3490196 0.1607843 1" />
            </material>
        </visual>
        <collision>
            <geometry>
                <mesh filename="package://abb_irb6660_support/meshes/irb6660/collision/base_link.stl" />
            </geometry>
            <material name="">
                <color rgba="1 1 0 1" />
            </material>
        </collision>
        <inertial>
            <mass value="0.1" />
            <origin xyz="0 0 0" rpy="0 0 0" />
            <inertia ixx="0.03" iyy="0.03" izz="0.03" ixy="0.0" ixz="0.0" iyz="0.0" />
        </inertial>
    </link>
    <link name="robot_link_1">
        <visual>
            <origin rpy="0 0 0" xyz="0 0 0" />
            <geometry>
                <mesh filename="package://abb_irb6660_support/meshes/irb6660/visual/link_1.stl" />
            </geometry>
            <material name="">
                <color rgba="0.7372549 0.3490196 0.1607843 1" />
            </material>
        </visual>
        <collision>
            <origin rpy="0 0 0" xyz="0 0 0" />
            <geometry>
                <mesh filename="package://abb_irb6660_support/meshes/irb6660/visual/link_1.stl" />
            </geometry>
            <material name="">
                <color rgba="1 1 0 1" />
            </material>
        </collision>
        <inertial>
            <mass value="0.1" />
            <origin xyz="0 0 0" rpy="0 0 0" />
            <inertia ixx="0.03" iyy="0.03" izz="0.03" ixy="0.0" ixz="0.0" iyz="0.0" />
        </inertial>
    </link>
    <link name="robot_link_2">
        <visual>
            <origin rpy="0 0 0" xyz="0 0 0" />
            <geometry>
                <mesh filename="package://abb_irb6660_support/meshes/irb6660_205_190/visual/link_2.stl" />
            </geometry>
            <material name="">
                <color rgba="0.7372549 0.3490196 0.1607843 1" />
            </material>
        </visual>
        <collision>
            <origin rpy="0 0 0" xyz="0 0 0" />
            <geometry>
                <mesh filename="package://abb_irb6660_support/meshes/irb6660_205_190/collision/link_2.stl" />
            </geometry>
            <material name="">
                <color rgba="1 1 0 1" />
            </material>
        </collision>
        <inertial>
            <mass value="0.1" />
            <origin xyz="0 0 0" rpy="0 0 0" />
            <inertia ixx="0.03" iyy="0.03" izz="0.03" ixy="0.0" ixz="0.0" iyz="0.0" />
        </inertial>
    </link>
    <link name="robot_link_3">
        <visual>
            <origin rpy="0 0 0" xyz="0 0 0" />
            <geometry>
                <mesh filename="package://abb_irb6660_support/meshes/irb6660/visual/link_3.stl" />
            </geometry>
            <material name="">
                <color rgba="0.7372549 0.3490196 0.1607843 1" />
            </material>
        </visual>
        <collision>
            <origin rpy="0 0 0" xyz="0 0 0" />
            <geometry>
                <mesh filename="package://abb_irb6660_support/meshes/irb6660/collision/link_3.stl" />
            </geometry>
            <material name="">
                <color rgba="1 1 0 1" />
            </material>
        </collision>
        <inertial>
            <mass value="0.1" />
            <origin xyz="0 0 0" rpy="0 0 0" />
            <inertia ixx="0.03" iyy="0.03" izz="0.03" ixy="0.0" ixz="0.0" iyz="0.0" />
        </inertial>
    </link>
    <link name="robot_link_4">
        <visual>
            <origin rpy="0 0 0" xyz="0 0 0" />
            <geometry>
                <mesh filename="package://abb_irb6660_support/meshes/irb6660_205_190/visual/link_4.stl" />
            </geometry>
            <material name="">
                <color rgba="0.7372549 0.3490196 0.1607843 1" />
            </material>
        </visual>
        <collision>
            <origin rpy="0 0 0" xyz="0 0 0" />
            <geometry>
                <mesh filename="package://abb_irb6660_support/meshes/irb6660_205_190/collision/link_4.stl" />
            </geometry>
            <material name="">
                <color rgba="1 1 0 1" />
            </material>
        </collision>
        <inertial>
            <mass value="0.1" />
            <origin xyz="0 0 0" rpy="0 0 0" />
            <inertia ixx="0.03" iyy="0.03" izz="0.03" ixy="0.0" ixz="0.0" iyz="0.0" />
        </inertial>
    </link>
    <link name="robot_link_5">
        <visual>
            <origin rpy="0 0 0" xyz="0 0 0" />
            <geometry>
                <mesh filename="package://abb_irb6660_support/meshes/irb6660/visual/link_5.stl" />
            </geometry>
            <material name="">
                <color rgba="0.7372549 0.3490196 0.1607843 1" />
            </material>
        </visual>
        <collision>
            <origin rpy="0 0 0" xyz="0 0 0" />
            <geometry>
                <mesh filename="package://abb_irb6660_support/meshes/irb6660/collision/link_5.stl" />
            </geometry>
            <material name="">
                <color rgba="1 1 0 1" />
            </material>
        </collision>
        <inertial>
            <mass value="0.1" />
            <origin xyz="0 0 0" rpy="0 0 0" />
            <inertia ixx="0.03" iyy="0.03" izz="0.03" ixy="0.0" ixz="0.0" iyz="0.0" />
        </inertial>
    </link>
    <link name="robot_link_6">
        <visual>
            <origin rpy="0 0 0" xyz="0 0 0" />
            <geometry>
                <mesh filename="package://abb_irb6660_support/meshes/irb6660/visual/link_6.stl" />
            </geometry>
            <material name="">
                <color rgba="0.1882353 0.1960784 0.2039216 1" />
            </material>
        </visual>
        <collision>
            <origin rpy="0 0 0" xyz="0 0 0" />
            <geometry>
                <mesh filename="package://abb_irb6660_support/meshes/irb6660/collision/link_6.stl" />
            </geometry>
            <material name="">
                <color rgba="1 1 0 1" />
            </material>
        </collision>
        <inertial>
            <mass value="0.1" />
            <origin xyz="0 0 0" rpy="0 0 0" />
            <inertia ixx="0.03" iyy="0.03" izz="0.03" ixy="0.0" ixz="0.0" iyz="0.0" />
        </inertial>
    </link>
    <!-- Balancer parallell to Link 2 -->
    <link name="robot_balancer">
        <visual>
            <!-- <origin xyz="0.2 0.0 -0.8145" rpy="0 0 0" /> -->
            <origin rpy="0 0 0" xyz="0 0 0" />
            <geometry>
                <mesh filename="package://abb_irb6660_support/meshes/irb6660_205_190/visual/link_bar.stl" />
            </geometry>
            <material name="">
                <color rgba="0.7372549 0.3490196 0.1607843 1" />
            </material>
        </visual>
        <collision>
            <!-- <origin xyz="0.2 0.0 -0.8145" rpy="0 0 0" /> -->
            <origin rpy="0 0 0" xyz="0 0 0" />
            <geometry>
                <mesh filename="package://abb_irb6660_support/meshes/irb6660_205_190/collision/link_bar.stl" />
            </geometry>
        </collision>
        <material name="">
            <color rgba="0.7372549 0.3490196 0.1607843 1" />
        </material>
        <inertial>
            <mass value="0.1" />
            <origin xyz="0 0 0" rpy="0 0 0" />
            <inertia ixx="0.03" iyy="0.03" izz="0.03" ixy="0.0" ixz="0.0" iyz="0.0" />
        </inertial>
    </link>
    <!-- Link Arm parallell to Link 3 -->
    <link name="robot_link_arm">
        <visual>
            <origin rpy="0 0 0" xyz="0 0 0" />
            <geometry>
                <mesh filename="package://abb_irb6660_support/meshes/irb6660/visual/link_arm.stl" />
            </geometry>
            <material name="">
                <color rgba="0.7372549 0.3490196 0.1607843 1" />
            </material>
        </visual>
        <collision>
            <origin rpy="0 0 0" xyz="0 0 0" />
            <geometry>
                <mesh filename="package://abb_irb6660_support/meshes/irb6660/collision/link_arm.stl" />
            </geometry>
        </collision>
        <material name="">
            <color rgba="0.7372549 0.3490196 0.1607843 1" />
        </material>
        <inertial>
            <mass value="0.1" />
            <origin xyz="0 0 0" rpy="0 0 0" />
            <inertia ixx="0.03" iyy="0.03" izz="0.03" ixy="0.0" ixz="0.0" iyz="0.0" />
        </inertial>
    </link>
    <!-- <link name="${prefix}link_arm"/> -->
    <link name="robot_fakelink" />
    <link name="robot_tool0" />
    <!-- End of Link List -->
    <!-- Joint List -->
    <!-- Joint 1 -Axis -->
    <joint name="robot_joint_1" type="revolute">
        <origin rpy="0 0 0" xyz="0 0 0.8145" />
        <parent link="robot_base_link" />
        <child link="robot_link_1" />
        <axis xyz="0 0 1" />
        <limit effort="0" lower="-3.141592653589793" upper="3.141592653589793" velocity="2.2689280275926285" />
    </joint>
    <!-- Joint 2 -Axis -->
    <joint name="robot_joint_2" type="revolute">
        <origin rpy="0 0 0" xyz="0.300 0 0" />
        <parent link="robot_link_1" />
        <child link="robot_link_2" />
        <axis xyz="0 1 0" />
        <limit effort="0" lower="-0.7330382858376184" upper="1.4835298641951802" velocity="2.2689280275926285" />
    </joint>
    <!-- Joint 3 -Axis -->
    <joint name="robot_joint_3" type="revolute">
        <origin rpy="0 0 0" xyz="0 0 0.700" />
        <parent link="robot_link_2" />
        <child link="robot_link_3" />
        <axis xyz="0 1 0" />
        <limit effort="0" lower="-1.2217304763960306" upper="1.2217304763960306" velocity="2.2689280275926285" />
    </joint>
    <!-- Joint 4 -Axis -->
    <joint name="robot_joint_4" type="revolute">
        <origin rpy="0 0 0" xyz="0 0 0.280" />
        <parent link="robot_link_3" />
        <child link="robot_link_4" />
        <axis xyz="1 0 0" />
        <limit effort="0" lower="-5.235987755982989" upper="5.235987755982989" velocity="2.6179938779914944" />
    </joint>
    <!-- Joint 5 -Axis -->
    <joint name="robot_joint_5" type="revolute">
        <origin rpy="0 0 0" xyz="0.893 0 0" />
        <parent link="robot_link_4" />
        <child link="robot_link_5" />
        <axis xyz="0 1 0" />
        <limit effort="0" lower="-2.0943951023931953" upper="2.0943951023931953" velocity="2.0943951023931953" />
    </joint>
    <!-- Joint 6 -Axis -->
    <joint name="robot_joint_6" type="revolute">
        <origin rpy="0 0 0" xyz="0.200 0 0" />
        <parent link="robot_link_5" />
        <child link="robot_link_6" />
        <axis xyz="1 0 0" />
        <limit effort="0" lower="-6.283185307179586" upper="6.283185307179586" velocity="3.3161255787892263" />
    </joint>
    <!-- EOAT -->
    <joint name="robot_joint_6-tool0" type="fixed">
        <origin rpy="0 1.5707963267948966 0" xyz="0 0 0" />
        <parent link="robot_link_6" />
        <child link="robot_tool0" />
    </joint>
    <joint name="robot_link1_adjustment" type="revolute">
        <origin rpy="0 0 0" xyz="0.300 0 0" />
        <parent link="robot_link_1" />
        <child link="robot_fakelink" />
        <axis xyz="0 1 0" />
        <mimic joint="robot_joint_2" multiplier="1" />
        <limit effort="0" lower="-1.2217304763960306" upper="1.2217304763960306" velocity="2.2689280275926285" />
    </joint>
    <joint name="robot_link_arm" type="revolute">
        <origin rpy="0 0 0" xyz="0 0 0" />
        <parent link="robot_fakelink" />
        <child link="robot_link_arm" />
        <axis xyz="0 1 0" />
        <mimic joint="robot_joint_3" multiplier="1" />
        <limit effort="0" lower="-1.2217304763960306" upper="1.2217304763960306" velocity="2.2689280275926285" />
    </joint>
    <joint name="robot_balancer" type="revolute">
        <!--Named balancer only to be interchangeable with motoman without errors-->
        <parent link="robot_link_arm" />
        <child link="robot_balancer" />
        <origin rpy="0 0 0" xyz="-0.5 0 0" />
        <axis xyz="0 1 0" />
        <mimic joint="robot_joint_3" multiplier="-1" />
        <limit effort="0" lower="-1.2217304763960306" upper="1.2217304763960306" velocity="2.2689280275926285" />
    </joint>
    <!-- End of joint List -->
    <!-- ROS base_link to ABB World Coordinates transform -->
    <link name="robot_base" />
    <joint name="robot_base_link-base" type="fixed">
        <origin rpy="0 0 0" xyz="0 0 0" />
        <parent link="robot_base_link" />
        <child link="robot_base" />
    </joint>
    <!-- Reference Link to Robot Base Link -->
    <joint name="robot_ref_to_base_link" type="fixed">
        <origin rpy="0.0 0.0 0.0" xyz="0.000 0.000 0.000" />
        <parent link="world" />
        <child link="robot_base_link" />
    </joint>
    <!-- End Effector -->
    <link name="robot_eef_mount" />
    <link name="robot_tcp" />
    <!-- Robot Tool0 to EEF Mount -->
    <joint name="robot_tool0_eef_mount_joint" type="fixed">
        <origin rpy="0.0 0.0 0.0" xyz="0.000 0.000 0.000" />
        <parent link="robot_tool0" />
        <child link="robot_eef_mount" />
    </joint>
    <!-- Robot EEF Mount to EEF TCP -->
    <joint name="robot_eef_mount_tcp_joint" type="fixed">
        <origin rpy="0.0 0.0 0.0" xyz="0.000 0.000 0.000" />
        <parent link="robot_eef_mount" />
        <child link="robot_tcp" />
    </joint>
    <!-- Environment Configuration-->
    <!-- Generate world-link-->
    <link name="world" />
    <transmission name="trans_robot_joint_1">
        <type>transmission_interface/SimpleTransmission</type>
        <joint name="robot_joint_1">
            <hardwareInterface>hardware_interface/EffortJointInterface</hardwareInterface>
        </joint>
        <actuator name="robot_joint_1_motor">
            <hardwareInterface>hardware_interface/EffortJointInterface</hardwareInterface>
            <mechanicalReduction>1</mechanicalReduction>
        </actuator>
    </transmission>
    <transmission name="trans_robot_joint_2">
        <type>transmission_interface/SimpleTransmission</type>
        <joint name="robot_joint_2">
            <hardwareInterface>hardware_interface/EffortJointInterface</hardwareInterface>
        </joint>
        <actuator name="robot_joint_2_motor">
            <hardwareInterface>hardware_interface/EffortJointInterface</hardwareInterface>
            <mechanicalReduction>1</mechanicalReduction>
        </actuator>
    </transmission>
    <transmission name="trans_robot_joint_3">
        <type>transmission_interface/SimpleTransmission</type>
        <joint name="robot_joint_3">
            <hardwareInterface>hardware_interface/EffortJointInterface</hardwareInterface>
        </joint>
        <actuator name="robot_joint_3_motor">
            <hardwareInterface>hardware_interface/EffortJointInterface</hardwareInterface>
            <mechanicalReduction>1</mechanicalReduction>
        </actuator>
    </transmission>
    <transmission name="trans_robot_joint_4">
        <type>transmission_interface/SimpleTransmission</type>
        <joint name="robot_joint_4">
            <hardwareInterface>hardware_interface/EffortJointInterface</hardwareInterface>
        </joint>
        <actuator name="robot_joint_4_motor">
            <hardwareInterface>hardware_interface/EffortJointInterface</hardwareInterface>
            <mechanicalReduction>1</mechanicalReduction>
        </actuator>
    </transmission>
    <transmission name="trans_robot_joint_5">
        <type>transmission_interface/SimpleTransmission</type>
        <joint name="robot_joint_5">
            <hardwareInterface>hardware_interface/EffortJointInterface</hardwareInterface>
        </joint>
        <actuator name="robot_joint_5_motor">
            <hardwareInterface>hardware_interface/EffortJointInterface</hardwareInterface>
            <mechanicalReduction>1</mechanicalReduction>
        </actuator>
    </transmission>
    <transmission name="trans_robot_joint_6">
        <type>transmission_interface/SimpleTransmission</type>
        <joint name="robot_joint_6">
            <hardwareInterface>hardware_interface/EffortJointInterface</hardwareInterface>
        </joint>
        <actuator name="robot_joint_6_motor">
            <hardwareInterface>hardware_interface/EffortJointInterface</hardwareInterface>
            <mechanicalReduction>1</mechanicalReduction>
        </actuator>
    </transmission>
    <transmission name="trans_robot_link1_adjustment">
        <type>transmission_interface/SimpleTransmission</type>
        <joint name="robot_link1_adjustment">
            <hardwareInterface>hardware_interface/EffortJointInterface</hardwareInterface>
        </joint>
        <actuator name="robot_link1_adjustment_motor">
            <hardwareInterface>hardware_interface/EffortJointInterface</hardwareInterface>
            <mechanicalReduction>1</mechanicalReduction>
        </actuator>
    </transmission>
    <transmission name="trans_robot_link_arm">
        <type>transmission_interface/SimpleTransmission</type>
        <joint name="robot_link_arm">
            <hardwareInterface>hardware_interface/EffortJointInterface</hardwareInterface>
        </joint>
        <actuator name="robot_link_arm_motor">
            <hardwareInterface>hardware_interface/EffortJointInterface</hardwareInterface>
            <mechanicalReduction>1</mechanicalReduction>
        </actuator>
    </transmission>
    <transmission name="trans_robot_balancer">
        <type>transmission_interface/SimpleTransmission</type>
        <joint name="robot_balancer">
            <hardwareInterface>hardware_interface/EffortJointInterface</hardwareInterface>
        </joint>
        <actuator name="robot_balancer_motor">
            <hardwareInterface>hardware_interface/EffortJointInterface</hardwareInterface>
            <mechanicalReduction>1</mechanicalReduction>
        </actuator>
    </transmission>
    <gazebo>
        <plugin name="gazebo_ros_control">
            <robotNamespace>/</robotNamespace>
        </plugin>
    </gazebo>
</robot>

